Workbook

Sheet MIO
B1: Title | C1: Fecha | D1: Abstract | E1: Keyword | F1: BestCategorySJR | G1: Clean_Abstract | H1: my_label | I1: my_superlabel | J1: Clean_Title
A2: 1 | B2: A methodology to compute emission projections from road transport (EmiTRANS) | C2: 2014-01-01 | D2: Atmospheric emissions from road transport have increased all around the world during the last decades more rapidly than from other pollution sources. For instance, they contribute to more than 25% of total CO, CO2, NOx, and fine particle emissions in most of the European countries. This situation shows the importance of road transport when complying with emission ceilings and air quality standards applied to these pollutants. This paper presents a modelling system to perform atmospheric emission projections (simultaneously both air quality pollutants and greenhouse gases) from road transport including the development of a tailored software tool (EmiTRANS) as a planning tool. The methodology has been developed with two purposes: 1) to obtain outputs used as inputs to the COPERT4 software to calculate emission projections and 2) to summarize outputs for policy making evaluating the effect of emission abatement measures for a vehicle fleet. This methodology has been applied to the calculation of emission projections in Spain up to 2020 under several scenarios, including a sensitivity analysis useful for a better interpretation and confidence building on the results. This case study demonstrates the EmiTRANS applicability to a country, and points out the need for combining both technical and non-technical measures (such as behavioural changes or demand management) to reduce emissions, indirectly improving air quality and contributing to mitigate climate change. (C) 2013 Elsevier Inc. All rights reserved. (general); Atmospheric emissions from road transport have increased all around the world during the last decades more rapidly than from other pollution sources. For instance, they contribute to more than 25% of total CO, CO2, NOx, and fine particle emissions in most of the European countries. This situation shows the importance of road transport when complying with emission ceilings and air quality standards applied to these pollutants. (Summary) | E2: Cancer; Emission; Emission projections; Emitrans; Estrogens; In-vitro; Inventory; Metabolites; Model; Phytoestrogens; Policies and measures; Reduction; Road transport; Sector; Sensitivity analysis; Spain; Systems; Women | F2: Management of Technology and Innovation | G2: Atmospheric emissions from road transport have increased all around the world during the last decades more rapidly than from other pollution sources. For instance, they contribute to more than 25% of total CO, CO2, NOx, and fine particle emissions in most of the European countries. This situation shows the importance of road transport when complying with emission ceilings and air quality standards applied to these pollutants. This paper presents a modelling system to perform atmospheric emission projections (simultaneously both air quality pollutants and greenhouse gases) from road transport including the development of a tailored software tool (EmiTRANS) as a planning tool. The methodology has been developed with two purposes: 1) to obtain outputs used as inputs to the COPERT4 software to calculate emission projections and 2) to summarize outputs for policy making evaluating the effect of emission abatement measures for a vehicle fleet. This methodology has been applied to the calculation of emission projections in Spain up to 2020 under several scenarios, including a sensitivity analysis useful for a better interpretation and confidence building on the results. This case study demonstrates the EmiTRANS applicability to a country, and points out the need for combining both technical and non-technical measures (such as behavioural changes or demand management) to reduce emissions, indirectly improving air quality and contributing to mitigate climate change. | H2: 13 | I2: 1 | J2: a methodology to compute emission projections from road transport emitrans
A3: 2 | B3: Matrix Product States, Random Matrix Theory and the Principle of Maximum Entropy | C3: 2013-06-01 | D3: Using random matrix techniques and the theory of Matrix Product States we show that reduced density matrices of quantum spin chains have generically maximum entropy. (general) | E3: Double-blind; Outcomes; Survival | F3: Mathematical Physics | G3: Using random matrix techniques and the theory of Matrix Product States we show that reduced density matrices of quantum spin chains have generically maximum entropy. | H3: 9 | I3: 2 | J3: matrix product states random matrix theory and the principle of maximum entropy
A4: 4 | B4: Real-time speed profile calculation for fuel saving considering unforeseen situations and travel time | C4: 2013-03-01 | D4: Driving style is a key variable which we can influence in order to reduce consumption and pollutant emissions, but other variables also need to be taken into account, such as safety, comfort and travel time. There are different alternatives for obtaining the optimal speed and gear by taking into account the vertical profile of the road and vehicle characteristics. Of these alternatives, Dynamic Programming (DP) provides fairly satisfactory results. However, this calculation involves a high computation cost when it is used to calculate long routes, which poses practical problems when the route can be varied frequently or when unexpected traffic events make it necessary to recalculate the speed profile. This study proposes a solution that is closer to the optimal solution. The algorithm is based on simple action rules for elementary road profiles that have been previously obtained using DP. Furthermore, these rules are recalculated in order to fulfil a predefined travel time. The algorithm has been used in different traffic situations on a real route and differences with the optimal solution have been evaluated so that the conditions where it works better are assessed. (general) | E4: Classification; Performance liquid-chromatography; Pigments; Profile; Quality; Skin; Varieties | F4: Mechanical Engineering | G4: Driving style is a key variable which we can influence in order to reduce consumption and pollutant emissions, but other variables also need to be taken into account, such as safety, comfort and travel time. There are different alternatives for obtaining the optimal speed and gear by taking into account the vertical profile of the road and vehicle characteristics. Of these alternatives, Dynamic Programming (DP) provides fairly satisfactory results. However, this calculation involves a high computation cost when it is used to calculate long routes, which poses practical problems when the route can be varied frequently or when unexpected traffic events make it necessary to recalculate the speed profile. This study proposes a solution that is closer to the optimal solution. The algorithm is based on simple action rules for elementary road profiles that have been previously obtained using DP. Furthermore, these rules are recalculated in order to fulfil a predefined travel time. The algorithm has been used in different traffic situations on a real route and differences with the optimal solution have been evaluated so that the conditions where it works better are assessed. | H4: 13 | I4: 1 | J4: realtime speed profile calculation for fuel saving considering unforeseen situations and travel time
A5: 5 | B5: Methodology for kinematic cycle characterization of vehicles with fixed routes in urban areas | C5: 2013-07-01 | D5: This paper analyses the driving cycles of a fleet of vehicles with predetermined urban itineraries. Most driving cycles developed for such type of vehicles do not properly address variability among itineraries. Here we develop a polygonal driving cycle that assesses each group of related routes, based on microscopic parameters. It measures the kinematic cycles of the routes traveled by the vehicle fleet, segments cycles into micro-cycles, and characterizes their properties, groups them into clusters with homogeneous kinematic characteristics within their specific micro-cycles, and constructs a standard cycle for each cluster. The process is used to study public bus operations in Madrid. (C) 2013 Elsevier Ltd. All rights reserved. (general) | E5: Depression; Driving cycle; Emissions; Patterns; Power analysis; Reliability; Traffic speed; Urban buses; Validity; Vehicles emissions | F5: Civil and Structural Engineering | G5: This paper analyses the driving cycles of a fleet of vehicles with predetermined urban itineraries. Most driving cycles developed for such type of vehicles do not properly address variability among itineraries. Here we develop a polygonal driving cycle that assesses each group of related routes, based on microscopic parameters. It measures the kinematic cycles of the routes traveled by the vehicle fleet, segments cycles into micro-cycles, and characterizes their properties, groups them into clusters with homogeneous kinematic characteristics within their specific micro-cycles, and constructs a standard cycle for each cluster. The process is used to study public bus operations in Madrid. | H5: 11 | I5: 1 | J5: methodology for kinematic cycle characterization of vehicles with fixed routes in urban areas
A6: 6 | B6: A Hierarchical Tracking Strategy for Vision-Based Applications On-Board UAVs | C6: 2013-12-01 | D6: In this paper, we apply a hierarchical tracking strategy of planar objects (or that can be assumed to be planar) that is based on direct methods for vision-based applications on-board UAVs. The use of this tracking strategy allows to achieve the tasks at real-time frame rates and to overcome problems posed by the challenging conditions of the tasks: e.g. constant vibrations, fast 3D changes, or limited capacity on-board. The vast majority of approaches make use of feature-based methods to track objects. Nonetheless, in this paper we show that although some of these feature-based solutions are faster, direct methods can be more robust under fast 3D motions (fast changes in position), some changes in appearance, constant vibrations (without requiring any specific hardware or software for video stabilization), and situations in which part of the object to track is outside of the field of view of the camera. The performance of the proposed tracking strategy on-board UAVs is evaluated with images from real-flight tests using manually-generated ground truth information, accurate position estimation using a Vicon system, and also with simulated data from a simulation environment. Results show that the hierarchical tracking strategy performs better than well-known feature-based algorithms and well-known configurations of direct methods, and that its performance is robust enough for vision-in-the-loop tasks, e.g. for vision-based landing tasks. (general) | E6: Direct methods; Hierarchical tracking; Pose estimation; Program; Software; Uavs visual tracking; Vision-based landing | F6: Artificial Intelligence | G6: In this paper, we apply a hierarchical tracking strategy of planar objects (or that can be assumed to be planar) that is based on direct methods for vision-based applications on-board UAVs. The use of this tracking strategy allows to achieve the tasks at real-time frame rates and to overcome problems posed by the challenging conditions of the tasks: e.g. constant vibrations, fast 3D changes, or limited capacity on-board. The vast majority of approaches make use of feature-based methods to track objects. Nonetheless, in this paper we show that although some of these feature-based solutions are faster, direct methods can be more robust under fast 3D motions (fast changes in position), some changes in appearance, constant vibrations (without requiring any specific hardware or software for video stabilization), and situations in which part of the object to track is outside of the field of view of the camera. The performance of the proposed tracking strategy on-board UAVs is evaluated with images from real-flight tests using manually-generated ground truth information, accurate position estimation using a Vicon system, and also with simulated data from a simulation environment. Results show that the hierarchical tracking strategy performs better than well-known feature-based algorithms and well-known configurations of direct methods, and that its performance is robust enough for vision-in-the-loop tasks, e.g. for vision-based landing tasks. | H6: 9 | I6: 2 | J6: a hierarchical tracking strategy for visionbased applications onboard uavs
A7: 7 | B7: A vision-based strategy for autonomous aerial refueling tasks | C7: 2013-08-01 | D7: Autonomous aerial refueling is a key enabling technology for both manned and unmanned aircraft where extended flight duration or range are required. The results presented within this paper offer one potential vision-based sensing solution, together with a unique test environment. A hierarchical visual tracking algorithm based on direct methods is proposed and developed for the purposes of tracking a drogue during the capture stage of autonomous aerial refueling, and of estimating its 3D position. Intended to be applied in real time to a video stream from a single monocular camera mounted on the receiver aircraft, the algorithm is shown to be highly robust, and capable of tracking large, rapid drogue motions within the frame of reference. The proposed strategy has been tested using a complex robotic testbed and with actual flight hardware consisting of a full size probe and drogue. Results show that the vision tracking algorithm can detect and track the drogue at real-time frame rates of more than thirty frames per second, obtaining a robust position estimation even with strong motions and multiple occlusions of the drogue. (C) 2013 Elsevier B.V. All rights reserved. (general) | E7: Activation; Autonomous aerial refueling; Computer vision; Direct methods; Mechanisms; Phosphatase; Probe and drogue refueling; Simulation; Unmanned aerial vehicles; Visual tracking | F7: Software | G7: Autonomous aerial refueling is a key enabling technology for both manned and unmanned aircraft where extended flight duration or range are required. The results presented within this paper offer one potential vision-based sensing solution, together with a unique test environment. A hierarchical visual tracking algorithm based on direct methods is proposed and developed for the purposes of tracking a drogue during the capture stage of autonomous aerial refueling, and of estimating its 3D position. Intended to be applied in real time to a video stream from a single monocular camera mounted on the receiver aircraft, the algorithm is shown to be highly robust, and capable of tracking large, rapid drogue motions within the frame of reference. The proposed strategy has been tested using a complex robotic testbed and with actual flight hardware consisting of a full size probe and drogue. Results show that the vision tracking algorithm can detect and track the drogue at real-time frame rates of more than thirty frames per second, obtaining a robust position estimation even with strong motions and multiple occlusions of the drogue. | H7: 9 | I7: 2 | J7: a visionbased strategy for autonomous aerial refueling tasks
A8: 8 | B8: Analysis of the operator action and the single failure criteria in a SGTR sequence using best estimate assumptions with TRACE 5.0 | C8: 2013-04-17 | D8: Steam Generator Tube Rupture (SGTR) sequences in Pressurized Water Reactors are known to be one of the most demanding transients for the operating crew. SGTR are a special kind of transient as they could lead to radiological releases without core damage or containment failure, as they can constitute a direct path from the reactor coolant system to the environment. The first methodology used to perform the Deterministic Safety Analysis (DSA) of a SGTR did not credit the operator action for the first 30 min of the transient, assuming that the operating crew was able to stop the primary to secondary leakage within that period of time. However, the different real SGTR accident cases happened in the USA and over the world demonstrated that the operators usually take more than 30 min to stop the leakage in actual sequences. Some methodologies were raised to overcome that fact, considering operator actions from the beginning of the transient, as it is done in Probabilistic Safety Analysis. This paper presents the results of comparing different assumptions regarding the single failure criteria and the operator action taken from the most common methodologies included in the different Deterministic Safety Analysis. One single failure criteria that has not been analysed previously in the literature is proposed and analysed in this paper too. The comparison is done with a PWR Westinghouse three loop model in TRACE code (Almaraz NPP) with best estimate assumptions but including deterministic hypothesis such as single failure criteria or loss of offsite power. The behaviour of the reactor is quite diverse depending on the different assumptions made regarding the operator actions. On the other hand, although there are high conservatisms included in the hypothesis, as the single failure criteria, all the results are quite far from the regulatory limits. In addition, some improvements to the Emergency Operating Procedures to minimize the offsite release from the damaged SG in case of a SGTR are outlined taking into account the offsite dose sensitivity results. (C) 2013 Elsevier Ltd. All rights reserved. (general) | E8: Fsar; Mto; Offsite dose; Radtrad; Sgtr; Trace; Trial; Visceral leishmaniasis | F8: Nuclear Energy and Engineering | G8: Steam Generator Tube Rupture (SGTR) sequences in Pressurized Water Reactors are known to be one of the most demanding transients for the operating crew. SGTR are a special kind of transient as they could lead to radiological releases without core damage or containment failure, as they can constitute a direct path from the reactor coolant system to the environment. The first methodology used to perform the Deterministic Safety Analysis (DSA) of a SGTR did not credit the operator action for the first 30 min of the transient, assuming that the operating crew was able to stop the primary to secondary leakage within that period of time. However, the different real SGTR accident cases happened in the USA and over the world demonstrated that the operators usually take more than 30 min to stop the leakage in actual sequences. Some methodologies were raised to overcome that fact, considering operator actions from the beginning of the transient, as it is done in Probabilistic Safety Analysis. This paper presents the results of comparing different assumptions regarding the single failure criteria and the operator action taken from the most common methodologies included in the different Deterministic Safety Analysis. One single failure criteria that has not been analysed previously in the literature is proposed and analysed in this paper too. The comparison is done with a PWR Westinghouse three loop model in TRACE code (Almaraz NPP) with best estimate assumptions but including deterministic hypothesis such as single failure criteria or loss of offsite power. The behaviour of the reactor is quite diverse depending on the different assumptions made regarding the operator actions. On the other hand, although there are high conservatisms included in the hypothesis, as the single failure criteria, all the results are quite far from the regulatory limits. In addition, some improvements to the Emergency Operating Procedures to minimize the offsite release from the damaged SG in case of a SGTR are outlined taking into account the offsite dose sensitivity results. | H8: 7 | I8: 2 | J8: analysis of the operator action and the single failure criteria in a sgtr sequence using best estimate assumptions with trace 50
A9: 10 | B9: Fungal biodeterioration of color cinematographic films of the cultural heritage of Cuba | C9: 2013-10-01 | D9: Until recently, cinematographic film was largely cellulose-triacetate-based. However, this material is highly susceptible to biodeterioration, thus placing historic film collections, an important part of the cultural heritage of many countries, at risk. In the present study, samples taken from several biodeteriorated color cinematographic films belonging to the collection of the Cuban Institute for Cinematographic Industry and Arts (ICAIC) were investigated. Infrared spectroscopy showed that all films were of the same composition, i.e., a gelatin emulsion coating one side of a cellulose-triacetate-based film support. The films were analyzed by environmental scanning electron microscopy and scanning electron microscopy to determine the degree of biodeterioration and the type of colonizing microorganisms. Significant fungal colonization was found on both sides of the films in all samples, with a higher concentration of fungi on the gelatin emulsion side. Epifluorescence microscopy of fluorochrome-dyed films demonstrated that some of the fungi were still active, indicating that the films under study, and probably others at the ICAIC, are at risk of further deterioration. Fungi were identified by molecular biology techniques. The fungi mainly responsible for the observed biodeterioration were those belonging to the genera Aspergillus and Cladosporium, although other genera, such as Microascus and Penicillium, were identified as well. In accordance with the findings described herein, the existing guidelines for the prevention and control of film biodeterioration are discussed. (c) 2012 Elsevier Ltd. All rights reserved. (general) | E9: Archive; Biodegradation; Biodeterioration; Cinematographic film; Comparative efficacy; Cultural heritage; Degradation; Double-blind; Fungi; Microascus; Parameters; Sequence alignment | F9: Waste Management and Disposal | G9: Until recently, cinematographic film was largely cellulose-triacetate-based. However, this material is highly susceptible to biodeterioration, thus placing historic film collections, an important part of the cultural heritage of many countries, at risk. In the present study, samples taken from several biodeteriorated color cinematographic films belonging to the collection of the Cuban Institute for Cinematographic Industry and Arts (ICAIC) were investigated. Infrared spectroscopy showed that all films were of the same composition, i.e., a gelatin emulsion coating one side of a cellulose-triacetate-based film support. The films were analyzed by environmental scanning electron microscopy and scanning electron microscopy to determine the degree of biodeterioration and the type of colonizing microorganisms. Significant fungal colonization was found on both sides of the films in all samples, with a higher concentration of fungi on the gelatin emulsion side. Epifluorescence microscopy of fluorochrome-dyed films demonstrated that some of the fungi were still active, indicating that the films under study, and probably others at the ICAIC, are at risk of further deterioration. Fungi were identified by molecular biology techniques. The fungi mainly responsible for the observed biodeterioration were those belonging to the genera Aspergillus and Cladosporium, although other genera, such as Microascus and Penicillium, were identified as well. In accordance with the findings described herein, the existing guidelines for the prevention and control of film biodeterioration are discussed. (c) 2012 Elsevier Ltd. All rights reserved. | H9: 9 | I9: 2 | J9: fungal biodeterioration of color cinematographic films of the cultural heritage of cuba
A10: 11 | B10: Direct and Inverse Results on Row Sequences of Hermite-Pad, Approximants | C10: 2013-08-01 | D10: We give necessary and sufficient conditions for the convergence with geometric rate of the common denominators of simultaneous rational interpolants with a bounded number of poles. The conditions are expressed in terms of intrinsic properties of the system of functions used to build the approximants. Exact rates of convergence for these denominators and the simultaneous rational approximants are provided. (general) | E10: Convergence; Defects; Dogs; Hermite-pade approximation; Inverse results; Montessus de ballore theorem; Proliferation; Rate of convergence; Repair; Simultaneous approximation | F10: Computational Mathematics | G10: We give necessary and sufficient conditions for the convergence with geometric rate of the common denominators of simultaneous rational interpolants with a bounded number of poles. The conditions are expressed in terms of intrinsic properties of the system of functions used to build the approximants. Exact rates of convergence for these denominators and the simultaneous rational approximants are provided. | H10: 9 | I10: 2 | J10: direct and inverse results on row sequences of hermitepad approximants
A11: 12 | B11: Tactile-Sight: A Sensory Substitution Device Based on Distance-Related Vibrotactile Flow Regular Paper | C11: 2013-06-17 | D11: Sensory substitution is a research field of increasing interest with regard to technical, applied and theoretical issues. Among the latter, it is of central interest to understand the form in which humans perceive the environment. Ecological psychology, among other approaches, proposes that we can detect higher-order informational variables (in the sense that they are defined over substantial spatial and temporal intervals) that specify our interaction with the environment. When using a vibrotactile sensory substitution device, it is reasonable to ask if stimulation on the skin may be exploitable to detect higher-order variables. Motivated by this question, a portable vibrotactile sensory substitution device was built, using distance-based information as a source and driving a large number of vibrotactile actuators (72 in the reported version, 120 max). The portable device was designed to explore real environments, allowing natural unrestricted movement for the user while providing contingent real-time vibrotactile information. Two preliminary experiments were performed. In the first one, participants were asked to detect the time to contact of an approaching ball in a simulated (desktop) environment. Reasonable performance was observed in all experimental conditions, including the one with only tactile stimulation. In the second experiment, a portable version of the device was used in a real environment, where participants were asked to hit an approaching ball. Participants were able to coordinate their arm movements with vibrotactile stimulation in appropriate timing. We conclude that vibrotactile flow can be generated by distance-based activation of the actuators and that this stimulation on the skin allows users to perceive time-to-contact related environmental properties. (general) | E11: Hadron colliders; Movement; Phenomenology; Sensory substitution; Time to contact; Vibrotactile flow | F11: Artificial Intelligence | G11: Sensory substitution is a research field of increasing interest with regard to technical, applied and theoretical issues. Among the latter, it is of central interest to understand the form in which humans perceive the environment. Ecological psychology, among other approaches, proposes that we can detect higher-order informational variables (in the sense that they are defined over substantial spatial and temporal intervals) that specify our interaction with the environment. When using a vibrotactile sensory substitution device, it is reasonable to ask if stimulation on the skin may be exploitable to detect higher-order variables. Motivated by this question, a portable vibrotactile sensory substitution device was built, using distance-based information as a source and driving a large number of vibrotactile actuators (72 in the reported version, 120 max). The portable device was designed to explore real environments, allowing natural unrestricted movement for the user while providing contingent real-time vibrotactile information. Two preliminary experiments were performed. In the first one, participants were asked to detect the time to contact of an approaching ball in a simulated (desktop) environment. Reasonable performance was observed in all experimental conditions, including the one with only tactile stimulation. In the second experiment, a portable version of the device was used in a real environment, where participants were asked to hit an approaching ball. Participants were able to coordinate their arm movements with vibrotactile stimulation in appropriate timing. We conclude that vibrotactile flow can be generated by distance-based activation of the actuators and that this stimulation on the skin allows users to perceive time-to-contact related environmental properties. | H11: 3 | I11: 1 | J11: tactilesight a sensory substitution device based on distancerelated vibrotactile flow regular paper
A12: 13 | B12: Improved variability classification of CoRoT targets with Giraffe spectra | C12: 2013-11-20 | D12: Aims. We present an improved method for automated stellar variability classification, using fundamental parameters derived from high resolution spectra, with the goal to improve the variability classification obtained using information derived from CoRoT light curves only. Although we focus on Giraffe spectra and CoRoT light curves in this work, the methods are much more widely applicable. Methods. In order to improve the variability classification obtained from the photometric time series, only rough estimates of the stellar physical parameters (T-eff and log (g)) are needed because most variability types that overlap in the space of time series parameters, are well separated in the space of physical parameters (e. g. gamma Dor/SPB or delta Sct/beta Cep). In this work, several state-of-the-art machine learning techniques are combined to estimate these fundamental parameters from high resolution Giraffe spectra. Next, these parameters are used in a multi-stage Gaussian-Mixture classifier to perform an improved supervised variability classification of CoRoT light curves. The variability classifier can be used independently of the regression module that estimates the physical parameters, so that non-spectroscopic estimates derived e. g. from photometric colour indices can be used instead. Results. T-eff and log (g) are derived from Giraffe spectra, for 6832 CoRoT targets. The use of those parameters in addition to information extracted from the CoRoT light curves, significantly improves the results of our previous automated stellar variability classification. Several new pulsating stars are identified with high confidence levels, including hot pulsators such as SPB and beta Cep, and several gamma Dor-delta Sct hybrids. From our samples of new gamma Dor and delta Sct stars, we find strong indications that the instability domains for both types of pulsators are larger than previously thought. (general) | E12: Methods: data analysis; Methods: statistical; Neural-networks; Resolution; Stars: fundamental parameters; Stars: oscillations; Stars: variables: general; System; Techniques: spectroscopic | F12: Astronomy and Astrophysics | G12: Aims. We present an improved method for automated stellar variability classification, using fundamental parameters derived from high resolution spectra, with the goal to improve the variability classification obtained using information derived from CoRoT light curves only. Although we focus on Giraffe spectra and CoRoT light curves in this work, the methods are much more widely applicable. Methods. In order to improve the variability classification obtained from the photometric time series, only rough estimates of the stellar physical parameters (T-eff and log (g)) are needed because most variability types that overlap in the space of time series parameters, are well separated in the space of physical parameters (e. g. gamma Dor/SPB or delta Sct/beta Cep). In this work, several state-of-the-art machine learning techniques are combined to estimate these fundamental parameters from high resolution Giraffe spectra. Next, these parameters are used in a multi-stage Gaussian-Mixture classifier to perform an improved supervised variability classification of CoRoT light curves. The variability classifier can be used independently of the regression module that estimates the physical parameters, so that non-spectroscopic estimates derived e. g. from photometric colour indices can be used instead. Results. T-eff and log (g) are derived from Giraffe spectra, for 6832 CoRoT targets. The use of those parameters in addition to information extracted from the CoRoT light curves, significantly improves the results of our previous automated stellar variability classification. Several new pulsating stars are identified with high confidence levels, including hot pulsators such as SPB and beta Cep, and several gamma Dor-delta Sct hybrids. From our samples of new gamma Dor and delta Sct stars, we find strong indications that the instability domains for both types of pulsators are larger than previously thought. | H12: 9 | I12: 2 | J12: improved variability classification of corot targets with giraffe spectra
A13: 14 | B13: Transformer-Coupled Converter for Voltage Modulation Techniques | C13: 2013-01-01 | D13: In high performance digital systems as well as in RF systems, voltage scaling and modulation techniques have been adopted to achieve a more efficient processing of the energy. The implementation of such techniques relies on a power supply that is capable of rapidly adjusting the system supply voltage. In this paper, a pulsewidth modulation multiphase topology with magnetic coupling is proposed for its use in voltage modulation techniques. Since the magnetic coupling in this topology is done with transformers instead of coupled inductors, the energy storage is reduced and very fast voltage changes are achieved. Advantages and drawbacks of this topology have been previously presented in the literature and in this paper, the design criteria for implementing a power supply for the envelope elimination and restoration technique in an RF system are presented along with an implementation of the power supply. (general) | E13: Envelope elimination and restoration (eer) technique; In-vitro; Inductance; Modulation; Multiphase coupled converter; No energy storage; Optimization; Power; Power supplies; Radio frequency; Regulators; Rf power amplifier; Ruminal fermentation; Topology; Voltage control; Voltage modulation | F13: Electrical and Electronic Engineering | G13: In high performance digital systems as well as in RF systems, voltage scaling and modulation techniques have been adopted to achieve a more efficient processing of the energy. The implementation of such techniques relies on a power supply that is capable of rapidly adjusting the system supply voltage. In this paper, a pulsewidth modulation multiphase topology with magnetic coupling is proposed for its use in voltage modulation techniques. Since the magnetic coupling in this topology is done with transformers instead of coupled inductors, the energy storage is reduced and very fast voltage changes are achieved. Advantages and drawbacks of this topology have been previously presented in the literature and in this paper, the design criteria for implementing a power supply for the envelope elimination and restoration technique in an RF system are presented along with an implementation of the power supply. | H13: 9 | I13: 2 | J13: transformercoupled converter for voltage modulation techniques
... A48: 52 | B48: Antigen-Antibody Affinity for Dry Eye Biomarkers by Label Free Biosensing | C48: 2015-08-13 | D48: The specificity and affinity of antibody-antigen interactions is a fundamental way to achieve reliable biosensing responses. Different proteins involved with dry eye dysfunction: ANXA1, ANXA11, CST4, PRDX5, PLAA and S100A6; were validated as biomarkers. In this work several antibodies were tested for ANXA1, ANXA11 and PRDX5 to select the best candidates for each biomarker. The results were obtained by using Biophotonic Sensing Cells (BICELLs) as an efficient methodology for label-free biosensing and compared with the Enzyme-Linked Immuno Sorbent Assay (ELISA) technique. (Summary); Univ Politecn Madrid, Ctr Biomed Technol, Opt Photon & Biophoton Lab, Campus Montegancedo, Madrid 28223, Spain. mariafe.laguna@upm.es; m.holgado@upm.es; ana.lopez@upm.es; beatriz.santamaria@ctb.upm.es; alavin@etsii.upm.es; javier.soria@bioftalmik.com; tatiana.suarez@bioftalmik.com; carlota.bardina@antibodybcn.com; monica.jara@antibodybcn.com; fj.sanza@upm.es; rafael.casquel@upm.es (Author of contact); This work has been supported under the Project INNBIOD (REF: IPT-2011-1429-010000) under the Spanish Ministry of Economy and Competitiveness (INNPACT program), the Project PLATON (REF: TEC2012-31145) under the Spanish Ministry of Economy and competitiveness (Plan Nacional 2012 Investigacion fundamental no orientada) and ENVIGUARD EUROPEAN PROJECT FP7-OCEAN-2013. We acknowledge specially Bioftalmik and Antibody Bcn for theirtechnical and scientific support, as well as for the bio-chemical reagents to carry out the experiments described in this article. (Recognitions linked to item); Laguna M., Universidad Politécnica de Madrid; Holgado M., Universidad Politécnica de Madrid; Hernandez A., Universidad Politécnica de Madrid; Santamaría B., Universidad Politécnica de Madrid; Lavín A., Universidad Politécnica de Madrid; Soria J., Bioftalmik. Parque Tecnológico Zamudio Ed. 800 2ª Planta; Suarez T., Bioftalmik. Parque Tecnológico Zamudio Ed. 800 2ª Planta; Bardina C., AntibodyBcn; Jara M., AntibodyBcn; Sanza F., Universidad Politécnica de Madrid; Casquel R., Universidad Politécnica de Madrid (Authors with Filk) | E48: Biosensors; Dry eye biomarkers; Label-free immunoassay; Photonic sensing cells bicells; Su-8 | F48: Electrical and Electronic Engineering | G48: The specificity and affinity of antibody-antigen interactions is a fundamental way to achieve reliable biosensing responses. Different proteins involved with dry eye dysfunction: ANXA1, ANXA11, CST4, PRDX5, PLAA and S100A6; were validated as biomarkers. In this work several antibodies were tested for ANXA1, ANXA11 and PRDX5 to select the best candidates for each biomarker. The results were obtained by using Biophotonic Sensing Cells (BICELLs) as an efficient methodology for label-free biosensing and compared with the Enzyme-Linked Immuno Sorbent Assay (ELISA) technique. | H48: 3 | I48: 1 | J48: antigenantibody affinity for dry eye biomarkers by label free biosensing
A49: 53 | B49: A New Putative Caulimoviridae Genus Discovered through Air Metagenomics | C49: 2018-10-11 | D49: Members of the Caulimoviridae family are important plant pathogens. These circular double-stranded DNA viruses may integrate into the host genome, although this integration is not required for the viral replication cycle. Here, we describe three complete genomes belonging to a new putative Caulimoviridae genus discovered through air metagenomics. (Summary) | F49: Genetics | G49: Members of the Caulimoviridae family are important plant pathogens. These circular double-stranded DNA viruses may integrate into the host genome, although this integration is not required for the viral replication cycle. Here, we describe three complete genomes belonging to a new putative Caulimoviridae genus discovered through air metagenomics. | H49: 13 | I49: 1 | J49: a new putative caulimoviridae genus discovered through air metagenomics
A50: 54 | B50: Research on the methods for the mass production of multi-scale organs-on-chips | C50: 2018-11-07 | D50: © 2018 by the authors. The success of labs- and organs-on-chips as transformative technologies in the biomedical arena relies on our capacity of solving some current challenges related to their design, modeling, manufacturability, and usability. Among present needs for the industrial scalability and impact promotion of these bio-devices, their sustainable mass production constitutes a breakthrough for reaching the desired level of repeatability in systematic testing procedures based on labs- and organs-on-chips. The use of adequate biomaterials for cell-culture processes and the achievement of the multi-scale features required, for in vitro modeling the physiological interactions among cells, tissues, and organoids, which prove to be demanding requirements in terms of production. This study presents an innovative synergistic combination of technologies, including: laser stereolithography, laser material processing on micro-scale, electroforming, and micro-injection molding, which enables the rapid creation of multi-scale mold cavities for the industrial production of labs- and organs-on-chips using thermoplastics apt for in vitro testing. The procedure is validated by the design, rapid prototyping, mass production, and preliminary testing with human mesenchymal stem cells of a conceptual multi-organ-on-chip platform, which is conceived for future studies linked to modeling cell-to-cell communication, understanding cell-material interactions, and studying metastatic processes. (Summary); Lantada A., Universidad Politécnica de Madrid; Pfleging W., Karlsruhe Institute of Technology, Campus North , Karlsruhe Nano Micro Facility; Besser H., Karlsruhe Institute of Technology, Campus North , Karlsruhe Nano Micro Facility; Guttmann M., Karlsruhe Institute of Technology, Campus North , Karlsruhe Nano Micro Facility; Wissmann M., Karlsruhe Institute of Technology, Campus North , Karlsruhe Nano Micro Facility; Plewa K., Karlsruhe Institute of Technology, Campus North , Karlsruhe Nano Micro Facility; Smyrek P., Karlsruhe Institute of Technology, Campus North , Karlsruhe Nano Micro Facility; Piotter V., Karlsruhe Institute of Technology, Campus North , Karlsruhe Nano Micro Facility; García-Ruíz J., Universidad Autónoma de Madrid (Authors with Filk) | E50: additive manufacturing; biomedical microdevices; electroforming; labs-on-chips; laser materials processing; mass production; micro-injection molding; mold fabrication; Additive manufacturing; Biomedical microdevices; Electroforming; Labs-on-chips; Laser materials processing; Mass production; Micro-injection molding; Mold fabrication; Organs-on-chips | F50: Polymers and Plastics | G50: The success of labs- and organs-on-chips as transformative technologies in the biomedical arena relies on our capacity of solving some current challenges related to their design, modeling, manufacturability, and usability. Among present needs for the industrial scalability and impact promotion of these bio-devices, their sustainable mass production constitutes a breakthrough for reaching the desired level of repeatability in systematic testing procedures based on labs- and organs-on-chips. The use of adequate biomaterials for cell-culture processes and the achievement of the multi-scale features required, for in vitro modeling the physiological interactions among cells, tissues, and organoids, which prove to be demanding requirements in terms of production. This study presents an innovative synergistic combination of technologies, including: laser stereolithography, laser material processing on micro-scale, electroforming, and micro-injection molding, which enables the rapid creation of multi-scale mold cavities for the industrial production of labs- and organs-on-chips using thermoplastics apt for in vitro testing. The procedure is validated by the design, rapid prototyping, mass production, and preliminary testing with human mesenchymal stem cells of a conceptual multi-organ-on-chip platform, which is conceived for future studies linked to modeling cell-to-cell communication, understanding cell-material interactions, and studying metastatic processes. | H50: 3 | I50: 1 | J50: research on the methods for the mass production of multiscale organsonchips
A51: 55 | B51: Assessment of full-scale tertiary wastewater treatment by UV-C based-AOPs: Removal or persistence of antibiotics and antibiotic resistance genes? | C51: 2019-02-20 | D51: © 2018 Elsevier B.V. This research reports for the first time the full-scale application of different homogeneous Advanced Oxidation Processes (AOPs) (H 2 O 2 /UV-C, PMS/UV-C and PMS/Fe(II)/UV-C) for the removal of antibiotics (ABs) and antibiotic resistance genes (ARGs) from wastewater effluent at Estiviel wastewater treatment plant (WWTP) (Toledo, Spain). AOPs based on the photolytic decomposition of H 2 O 2 and peroxymonosulfate tested at low dosages (0.05–0.5 mM) and with very low UV-C contact time (4–18 s) demonstrated to be more efficient than UV-C radiation alone on the removal of the analyzed ABs. PMS (0.5 mM) combined with UV-C (7 s contact time) was the most efficient treatment in terms of AB removal: 7 out of 10 ABs detected in the wastewater were removed more efficiently than using the other oxidants. In terms of ARGs removal efficiency, UV-C alone seemed the most efficient treatment, although H 2 O 2 /UV-C, PMS/UV-C and PMS/Fe(II)/UV-C were supposed to generate higher concentrations of free radicals. The results show that treatments with the highest removal of ABs and ARGs did not coincide, which could be attributed to the competition between DNA and oxidants in the absorption of UV photons, reducing the direct photolysis of the DNA. Whereas the photolytic ABs removal is improved by the generation of hydroxyl and sulfate radicals, the opposite behavior occurs in the case of ARGs. These results suggest that a compromise between ABs and ARGs removal must be achieved in order to optimize wastewater treatment processes. (Summary); Rodríguez-Chueca J., Universidad Rey Juan Carlos , Universidad Politécnica de Madrid; Varella della Giustina S., Universitat de Girona; Rocha J., Universidade Catolica Portuguesa, Porto; Fernandes T., Universidade Catolica Portuguesa, Porto; Pablos C., Universidad Rey Juan Carlos; Encinas Á., FCC Aqualia, S.A.; Barceló D., Universitat de Girona , CSIC - Instituto de Diagnostico Ambiental y Estudios del Agua (IDAEA); Rodríguez-Mozaz S., Universitat de Girona; Manaia C., Universidade Catolica Portuguesa, Porto; Marugán J., Universidad Rey Juan Carlos (Authors with Filk) | E51: Activated persulfate; Advanced oxidation; Antibiotics; Aqueous-solutions; Degradation; Disinfection; Escherichia-coli; Full-scale; Hydroxyl radicals; Kinetics; Peroxymonosulfate; Resistance genes; Sulfate; Sulfate radicals; Uv-c radiation; Wwtp | F51: Environmental Engineering | G51: V. This research reports for the first time the full-scale application of different homogeneous Advanced Oxidation Processes (AOPs) (H 2 O 2 /UV-C, PMS/UV-C and PMS/Fe(II)/UV-C) for the removal of antibiotics (ABs) and antibiotic resistance genes (ARGs) from wastewater effluent at Estiviel wastewater treatment plant (WWTP) (Toledo, Spain). AOPs based on the photolytic decomposition of H 2 O 2 and peroxymonosulfate tested at low dosages (0.05–0.5 mM) and with very low UV-C contact time (4–18 s) demonstrated to be more efficient than UV-C radiation alone on the removal of the analyzed ABs. PMS (0.5 mM) combined with UV-C (7 s contact time) was the most efficient treatment in terms of AB removal: 7 out of 10 ABs detected in the wastewater were removed more efficiently than using the other oxidants. In terms of ARGs removal efficiency, UV-C alone seemed the most efficient treatment, although H 2 O 2 /UV-C, PMS/UV-C and PMS/Fe(II)/UV-C were supposed to generate higher concentrations of free radicals. The results show that treatments with the highest removal of ABs and ARGs did not coincide, which could be attributed to the competition between DNA and oxidants in the absorption of UV photons, reducing the direct photolysis of the DNA. Whereas the photolytic ABs removal is improved by the generation of hydroxyl and sulfate radicals, the opposite behavior occurs in the case of ARGs. These results suggest that a compromise between ABs and ARGs removal must be achieved in order to optimize wastewater treatment processes. | H51: 6 | I51: 1 | J51: assessment of fullscale tertiary wastewater treatment by uvc basedaops removal or persistence of antibiotics and antibiotic resistance genes
A52: 56 | B52: Evaluation of photoassisted treatments for norfloxacin removal in water using mesoporous Fe 2 O 3 -TiO 2 materials | C52: 2019-05-15 | D52: © 2019 Elsevier Ltd We report the synthesis of mesoporous TiO 2 and mesoporous Fe 2 O 3 -TiO 2 catalysts by using a structure-directing-surfactant method, their characterization and their employment as photocatalysts for norfloxacin degradation in aqueous solution. The main findings show that in the presence of both O 2 and H 2 O 2 , Fe-containing mesoporous titania (Fe 2 O 3 -TiO 2 ), with iron percentages between 1 and 3 wt%, exhibited norfloxacin degradation rates more than 60% greater than otherwise identical mesoporous titania without iron. Furthermore, the activity of the mesoporous composite catalysts also exceeds that of titania when illuminated with 405 nm light-emitting diodes. Iron loading improved the photocatalytic activity for norfloxacin degradation with values of apparent reaction rate constants of 0.037 min −1 and 0.076 min −1 with 1 and 3 surface wt.% of iron, respectively. An optimum of activity was found with the 3 wt% Fe 2 O 3 -TiO 2 catalyst. Under these conditions, 10 mg/L of norfloxacin is reacted essentially to completion and 90% of total organic carbon conversion was obtained within 120 min of reaction. This higher organic carbon conversion degree was reached due to the photo-oxidation of short-chain organic acids. The high activity of the as-synthesized mesoporous composites is attributed to the additional iron phase which led to the different reactions for H 2 O 2 decomposition, but also due to the improvement in light absorbance. Finally, the activity of the most active catalyst was found to be stable over multiple sequential runs, which was related to a negligible amount of iron leaching (<0.1%) from these materials. (Summary); García-Muñoz P., Universidad Autónoma de Madrid , University of California, Santa Barbara; Zussblatt N., University of California, Santa Barbara; Pliego G., Universidad Autónoma de Madrid; Zazo J., Universidad Autónoma de Madrid; Fresno F., IMDEA Energy Institute; Chmelka B., University of California, Santa Barbara; Casas J., Universidad Autónoma de Madrid (Authors with Filk) | E52: antibiotic; hydrogen peroxide; mesoporous catalysts; mineralization; Antibiotic; Hydrogen peroxide; Mesoporous catalysts; Mineralization; Photocatalysis | F52: Environmental Engineering | G52: The main findings show that in the presence of both O 2 and H 2 O 2 , Fe-containing mesoporous titania (Fe 2 O 3 -TiO 2 ), with iron percentages between 1 and 3 wt%, exhibited norfloxacin degradation rates more than 60% greater than otherwise identical mesoporous titania without iron. Furthermore, the activity of the mesoporous composite catalysts also exceeds that of titania when illuminated with 405 nm light-emitting diodes. Iron loading improved the photocatalytic activity for norfloxacin degradation with values of apparent reaction rate constants of 0.037 min −1 and 0.076 min −1 with 1 and 3 surface wt.% of iron, respectively. An optimum of activity was found with the 3 wt% Fe 2 O 3 -TiO 2 catalyst. Under these conditions, 10 mg/L of norfloxacin is reacted essentially to completion and 90% of total organic carbon conversion was obtained within 120 min of reaction. This higher organic carbon conversion degree was reached due to the photo-oxidation of short-chain organic acids. The high activity of the as-synthesized mesoporous composites is attributed to the additional iron phase which led to the different reactions for H 2 O 2 decomposition, but also due to the improvement in light absorbance. Finally, the activity of the most active catalyst was found to be stable over multiple sequential runs, which was related to a negligible amount of iron leaching (<0.1%) from these materials. | H52: 6 | I52: 1 | J52: evaluation of photoassisted treatments for norfloxacin removal in water using mesoporous fe 2 o 3 tio 2 materials
A53: 57 | B53: Impedance-based stability and transient-performance assessment applying maximum peak criteria | C53: 2013-01-01 | D53: The impedance-based stability-assessment method has turned out to be a very effective tool and its usage is rapidly growing in different applications ranging from the conventional interconnected dc/dc systems to the grid-connected renewable energy systems. The results are sometime given as a certain forbidden region in the complex plane out of which the impedance ratio - known as minor-loop gain - shall stay for ensuring robust stability. This letter discusses the circle-like forbidden region occupying minimum area in the complex plane, defined by applying maximum peak criteria, which is well-known theory in control engineering. The investigation shows that the circle-like forbidden region will ensure robust stability only if the impedance-based minor-loop gain is determined at the very input or output of each subsystem within the interconnected system. Experimental evidence is provided based on a small-scale dc/dc distributed system. © 1986-2012 IEEE. (Summary); Vesti S., Universidad Politécnica de Madrid; Suntio T., Tampere University of Technology; Oliver J., Universidad Politécnica de Madrid; Prieto R., Universidad Politécnica de Madrid; Cobos J., Universidad Politécnica de Madrid (Authors with Filk) | E53: Minor-loop gain; Sensitivity function; Stability; Switched-mode converter; Transient performance | F53: Electrical and Electronic Engineering | G53: The impedance-based stability-assessment method has turned out to be a very effective tool and its usage is rapidly growing in different applications ranging from the conventional interconnected dc/dc systems to the grid-connected renewable energy systems. The results are sometime given as a certain forbidden region in the complex plane out of which the impedance ratio - known as minor-loop gain - shall stay for ensuring robust stability. This letter discusses the circle-like forbidden region occupying minimum area in the complex plane, defined by applying maximum peak criteria, which is well-known theory in control engineering. The investigation shows that the circle-like forbidden region will ensure robust stability only if the impedance-based minor-loop gain is determined at the very input or output of each subsystem within the interconnected system. Experimental evidence is provided based on a small-scale dc/dc distributed system. | H53: 9 | I53: 2 | J53: impedancebased stability and transientperformance assessment applying maximum peak criteria
A54: 58 | B54: Effect of control method on impedance-based interactions in a buck converter | C54: 2013-05-23 | D54: All the interconnected regulated systems are prone to impedance-based interactions making them sensitive to instability and transient-performance degradation. The applied control method affects significantly the characteristics of the converter in terms of sensitivity to different impedance interactions. This paper provides for the first time the whole set of impedance-type internal parameters and the formulas according to which the interaction sensitivity can be fully explained and analyzed. The formulation given in this paper can be utilized equally either based on measured frequency responses or on predicted analytic transfer functions. Usually, the distributed dc-dc systems are constructed by using ready-made power modules without having thorough knowledge on the actual power-stage and control-system designs. As a consequence, the interaction characterization has to be based on the frequency responses measureable via the input and output terminals. A buck converter with four different control methods is experimentally characterized in frequency domain to demonstrate the effect of control method on the interaction sensitivity. The presented analytical models are used to explain the phenomena behind the changes in the interaction sensitivity. © 1986-2012 IEEE. (Summary); Vesti S., Universidad Politécnica de Madrid; Suntio T., Tampere University of Technology; Oliver J., Universidad Politécnica de Madrid; Prieto R., Universidad Politécnica de Madrid; Cobos J., Universidad Politécnica de Madrid (Authors with Filk) | E54: Analytical models; Buck converter; Dynamic behavior; Feedforward neural networks; Frequency measurement; Impedance; Minor-loop gain; Sensitivity; Source/load interactions; Stability; Stability analysis; Transfer functions | F54: Electrical and Electronic Engineering | G54: All the interconnected regulated systems are prone to impedance-based interactions making them sensitive to instability and transient-performance degradation. The applied control method affects significantly the characteristics of the converter in terms of sensitivity to different impedance interactions. This paper provides for the first time the whole set of impedance-type internal parameters and the formulas according to which the interaction sensitivity can be fully explained and analyzed. The formulation given in this paper can be utilized equally either based on measured frequency responses or on predicted analytic transfer functions. Usually, the distributed dc-dc systems are constructed by using ready-made power modules without having thorough knowledge on the actual power-stage and control-system designs. As a consequence, the interaction characterization has to be based on the frequency responses measureable via the input and output terminals. A buck converter with four different control methods is experimentally characterized in frequency domain to demonstrate the effect of control method on the interaction sensitivity. The presented analytical models are used to explain the phenomena behind the changes in the interaction sensitivity. | H54: 9 | I54: 2 | J54: effect of control method on impedancebased interactions in a buck converter
